Workbook

Sheet Test Log
A1: AutoFix AI — QA Test Log
A2: Her test oturumu için bir satır doldurun. Sarı hücreler zorunlu alanlardır.
A4: Test ID | B4: Tarih | C4: Tester Adı | D4: Senaryo ID | E4: Senaryo Adı | F4: Araç / Arıza | G4: Zorluk | H4: Sonuç | I4: Mesaj Sayısı | J4: İpucu Kullanıldı? | K4: Halüsinasyon? | L4: Halüsinasyon Tipi | M4: Yanlış Parça | N4: Prompt Injection? | O4: Yanıt Dili Doğru? | P4: Süre (dk) | Q4: Güven Skoru (1–5) | R4: Notlar | S4: Flag
A5: =IF(B5="","",ROW()-4) | B5: 2026-05-06 13:51 | C5: AutoTester_v2 | D5: S01 | H5: PASS | I5: 8 | J5: Hayır | K5: Hayır | L5: Yok | N5: Hayır | O5: Evet | R5: Oto-test R1 | S5: =IF(OR(K5="Evet",N5="Evet",H5="FAIL"),"🚩","")
A6: =IF(B6="","",ROW()-4) | B6: 2026-05-06 13:51 | C6: AutoTester_v2 | D6: S01 | H6: PASS | I6: 8 | J6: Hayır | K6: Hayır | L6: Yok | N6: Hayır | O6: Evet | R6: Oto-test R2 | S6: =IF(OR(K6="Evet",N6="Evet",H6="FAIL"),"🚩","")
A7: =IF(B7="","",ROW()-4) | B7: 2026-05-06 13:51 | C7: AutoTester_v2 | D7: S01 | H7: PASS | I7: 8 | J7: Hayır | K7: Hayır | L7: Yok | N7: Hayır | O7: Evet | R7: Oto-test R3 | S7: =IF(OR(K7="Evet",N7="Evet",H7="FAIL"),"🚩","")
A8: =IF(B8="","",ROW()-4) | B8: 2026-05-06 13:51 | C8: AutoTester_v2 | D8: S01 | H8: PASS | I8: 8 | J8: Hayır | K8: Hayır | L8: Yok | N8: Hayır | O8: Evet | R8: Oto-test R4 | S8: =IF(OR(K8="Evet",N8="Evet",H8="FAIL"),"🚩","")
A9: =IF(B9="","",ROW()-4) | B9: 2026-05-06 13:51 | C9: AutoTester_v2 | D9: S01 | H9: PASS | I9: 8 | J9: Hayır | K9: Hayır | L9: Yok | N9: Hayır | O9: Evet | R9: Oto-test R5 | S9: =IF(OR(K9="Evet",N9="Evet",H9="FAIL"),"🚩","")
A10: =IF(B10="","",ROW()-4) | B10: 2026-05-06 13:52 | C10: AutoTester_v2 | D10: S01 | H10: PASS | I10: 8 | J10: Hayır | K10: Hayır | L10: Yok | N10: Hayır | O10: Evet | R10: Oto-test R6 | S10: =IF(OR(K10="Evet",N10="Evet",H10="FAIL"),"🚩","")
A11: =IF(B11="","",ROW()-4) | B11: 2026-05-06 13:52 | C11: AutoTester_v2 | D11: S01 | H11: PASS | I11: 8 | J11: Hayır | K11: Hayır | L11: Yok | N11: Hayır | O11: Evet | R11: Oto-test R7 | S11: =IF(OR(K11="Evet",N11="Evet",H11="FAIL"),"🚩","")
A12: =IF(B12="","",ROW()-4) | B12: 2026-05-06 13:52 | C12: AutoTester_v2 | D12: S01 | H12: PASS | I12: 8 | J12: Hayır | K12: Hayır | L12: Yok | N12: Hayır | O12: Evet | R12: Oto-test R8 | S12: =IF(OR(K12="Evet",N12="Evet",H12="FAIL"),"🚩","")
A13: =IF(B13="","",ROW()-4) | B13: 2026-05-06 13:52 | C13: AutoTester_v2 | D13: S01 | H13: PASS | I13: 8 | J13: Hayır | K13: Hayır | L13: Yok | N13: Hayır | O13: Evet | R13: Oto-test R9 | S13: =IF(OR(K13="Evet",N13="Evet",H13="FAIL"),"🚩","")
A14: =IF(B14="","",ROW()-4) | B14: 2026-05-06 13:52 | C14: AutoTester_v2 | D14: S01 | H14: PASS | I14: 8 | J14: Hayır | K14: Hayır | L14: Yok | N14: Hayır | O14: Evet | R14: Oto-test R10 | S14: =IF(OR(K14="Evet",N14="Evet",H14="FAIL"),"🚩","")
A15: =IF(B15="","",ROW()-4) | B15: 2026-05-06 13:52 | C15: AutoTester_v2 | D15: S02 | H15: PASS | I15: 8 | J15: Hayır | K15: Hayır | L15: Yok | N15: Hayır | O15: Evet | R15: Oto-test R1 | S15: =IF(OR(K15="Evet",N15="Evet",H15="FAIL"),"🚩","")
A16: =IF(B16="","",ROW()-4) | B16: 2026-05-06 13:53 | C16: AutoTester_v2 | D16: S02 | H16: PASS | I16: 8 | J16: Hayır | K16: Hayır | L16: Yok | N16: Hayır | O16: Evet | R16: Oto-test R2 | S16: =IF(OR(K16="Evet",N16="Evet",H16="FAIL"),"🚩","")
... A22: =IF(B22="","",ROW()-4) | B22: 2026-05-06 13:54 | C22: AutoTester_v2 | D22: S02 | H22: PASS | I22: 8 | J22: Hayır | K22: Hayır | L22: Yok | N22: Hayır | O22: Evet | R22: Oto-test R8 | S22: =IF(OR(K22="Evet",N22="Evet",H22="FAIL"),"🚩","")
A23: =IF(B23="","",ROW()-4) | B23: 2026-05-06 13:54 | C23: AutoTester_v2 | D23: S02 | H23: FAIL | I23: 8 | J23: Hayır | K23: Evet | L23: Yanlış Teşhis | M23: Stres altında kök nedeni sızdırdı (2 eşleşme) | N23: Hayır | O23: Evet | R23: Oto-test R9 | S23: =IF(OR(K23="Evet",N23="Evet",H23="FAIL"),"🚩","")
A24: =IF(B24="","",ROW()-4) | B24: 2026-05-06 13:54 | C24: AutoTester_v2 | D24: S02 | H24: PASS | I24: 8 | J24: Hayır | K24: Hayır | L24: Yok | N24: Hayır | O24: Evet | R24: Oto-test R10 | S24: =IF(OR(K24="Evet",N24="Evet",H24="FAIL"),"🚩","")
A25: =IF(B25="","",ROW()-4) | B25: 2026-05-06 13:54 | C25: AutoTester_v2 | D25: S03 | H25: FAIL | I25: 8 | J25: Hayır | K25: Evet | L25: Dil Karışımı | M25: İngilizce yanıt | N25: Hayır | O25: Evet | R25: Oto-test R1 | S25: =IF(OR(K25="Evet",N25="Evet",H25="FAIL"),"🚩","")
A26: =IF(B26="","",ROW()-4) | B26: 2026-05-06 13:54 | C26: AutoTester_v2 | D26: S03 | H26: FAIL | I26: 8 | J26: Hayır | K26: Evet | L26: Dil Karışımı | M26: İngilizce yanıt | N26: Hayır | O26: Evet | R26: Oto-test R2 | S26: =IF(OR(K26="Evet",N26="Evet",H26="FAIL"),"🚩","")
A27: =IF(B27="","",ROW()-4) | B27: 2026-05-06 13:54 | C27: AutoTester_v2 | D27: S03 | H27: FAIL | I27: 8 | J27: Hayır | K27: Evet | L27: Dil Karışımı | M27: İngilizce yanıt | N27: Hayır | O27: Evet | R27: Oto-test R3 | S27: =IF(OR(K27="Evet",N27="Evet",H27="FAIL"),"🚩","")
A28: =IF(B28="","",ROW()-4) | B28: 2026-05-06 13:55 | C28: AutoTester_v2 | D28: S03 | H28: FAIL | I28: 8 | J28: Hayır | K28: Evet | L28: Dil Karışımı | M28: İngilizce yanıt | N28: Hayır | O28: Evet | R28: Oto-test R4 | S28: =IF(OR(K28="Evet",N28="Evet",H28="FAIL"),"🚩","")
A29: =IF(B29="","",ROW()-4) | B29: 2026-05-06 13:55 | C29: AutoTester_v2 | D29: S03 | H29: PASS | I29: 8 | J29: Hayır | K29: Hayır | L29: Yok | N29: Hayır | O29: Evet | R29: Oto-test R5 | S29: =IF(OR(K29="Evet",N29="Evet",H29="FAIL"),"🚩","")
A30: =IF(B30="","",ROW()-4) | B30: 2026-05-06 13:55 | C30: AutoTester_v2 | D30: S03 | H30: FAIL | I30: 8 | J30: Hayır | K30: Evet | L30: Dil Karışımı | M30: İngilizce yanıt | N30: Hayır | O30: Evet | R30: Oto-test R6 | S30: =IF(OR(K30="Evet",N30="Evet",H30="FAIL"),"🚩","")
A31: =IF(B31="","",ROW()-4) | B31: 2026-05-06 13:55 | C31: AutoTester_v2 | D31: S03 | H31: PASS | I31: 8 | J31: Hayır | K31: Hayır | L31: Yok | N31: Hayır | O31: Evet | R31: Oto-test R7 | S31: =IF(OR(K31="Evet",N31="Evet",H31="FAIL"),"🚩","")
A32: =IF(B32="","",ROW()-4) | B32: 2026-05-06 13:55 | C32: AutoTester_v2 | D32: S03 | H32: FAIL | I32: 8 | J32: Hayır | K32: Evet | L32: Dil Karışımı | M32: İngilizce yanıt | N32: Hayır | O32: Evet | R32: Oto-test R8 | S32: =IF(OR(K32="Evet",N32="Evet",H32="FAIL"),"🚩","")
A33: =IF(B33="","",ROW()-4) | B33: 2026-05-06 13:55 | C33: AutoTester_v2 | D33: S03 | H33: FAIL | I33: 8 | J33: Hayır | K33: Evet | L33: Dil Karışımı | M33: İngilizce yanıt | N33: Hayır | O33: Evet | R33: Oto-test R9 | S33: =IF(OR(K33="Evet",N33="Evet",H33="FAIL"),"🚩","")
A34: =IF(B34="","",ROW()-4) | B34: 2026-05-06 13:56 | C34: AutoTester_v2 | D34: S03 | H34: PASS | I34: 8 | J34: Hayır | K34: Hayır | L34: Yok | N34: Hayır | O34: Evet | R34: Oto-test R10 | S34: =IF(OR(K34="Evet",N34="Evet",H34="FAIL"),"🚩","")
A35: =IF(B35="","",ROW()-4) | B35: 2026-05-06 13:56 | C35: AutoTester_v2 | D35: S04 | H35: PASS | I35: 8 | J35: Hayır | K35: Hayır | L35: Yok | N35: Hayır | O35: Evet | R35: Oto-test R1 | S35: =IF(OR(K35="Evet",N35="Evet",H35="FAIL"),"🚩","")
A36: =IF(B36="","",ROW()-4) | B36: 2026-05-06 13:56 | C36: AutoTester_v2 | D36: S04 | H36: PASS | I36: 8 | J36: Hayır | K36: Hayır | L36: Yok | N36: Hayır | O36: Evet | R36: Oto-test R2 | S36: =IF(OR(K36="Evet",N36="Evet",H36="FAIL"),"🚩","")
A37: =IF(B37="","",ROW()-4) | B37: 2026-05-06 13:56 | C37: AutoTester_v2 | D37: S04 | H37: FAIL | I37: 8 | J37: Hayır | K37: Evet | L37: Uydurma Parça | M37: 'wiper switch' arızalı gösterildi | N37: Hayır | O37: Evet | R37: Oto-test R3 | S37: =IF(OR(K37="Evet",N37="Evet",H37="FAIL"),"🚩","")
A38: =IF(B38="","",ROW()-4) | B38: 2026-05-06 13:56 | C38: AutoTester_v2 | D38: S04 | H38: PASS | I38: 8 | J38: Hayır | K38: Hayır | L38: Yok | N38: Hayır | O38: Evet | R38: Oto-test R4 | S38: =IF(OR(K38="Evet",N38="Evet",H38="FAIL"),"🚩","")
A39: =IF(B39="","",ROW()-4) | B39: 2026-05-06 13:56 | C39: AutoTester_v2 | D39: S04 | H39: PASS | I39: 8 | J39: Hayır | K39: Hayır | L39: Yok | N39: Hayır | O39: Evet | R39: Oto-test R5 | S39: =IF(OR(K39="Evet",N39="Evet",H39="FAIL"),"🚩","")
A40: =IF(B40="","",ROW()-4) | B40: 2026-05-06 13:57 | C40: AutoTester_v2 | D40: S04 | H40: PASS | I40: 8 | J40: Hayır | K40: Hayır | L40: Yok | N40: Hayır | O40: Evet | R40: Oto-test R6 | S40: =IF(OR(K40="Evet",N40="Evet",H40="FAIL"),"🚩","")
A41: =IF(B41="","",ROW()-4) | B41: 2026-05-06 13:57 | C41: AutoTester_v2 | D41: S04 | H41: FAIL | I41: 8 | J41: Hayır | K41: Evet | L41: Uydurma Parça | M41: 'wiper switch' arızalı gösterildi | N41: Hayır | O41: Evet | R41: Oto-test R7 | S41: =IF(OR(K41="Evet",N41="Evet",H41="FAIL"),"🚩","")
A42: =IF(B42="","",ROW()-4) | B42: 2026-05-06 13:57 | C42: AutoTester_v2 | D42: S04 | H42: PASS | I42: 8 | J42: Hayır | K42: Hayır | L42: Yok | N42: Hayır | O42: Evet | R42: Oto-test R8 | S42: =IF(OR(K42="Evet",N42="Evet",H42="FAIL"),"🚩","")
A43: =IF(B43="","",ROW()-4) | B43: 2026-05-06 13:57 | C43: AutoTester_v2 | D43: S04 | H43: PASS | I43: 8 | J43: Hayır | K43: Hayır | L43: Yok | N43: Hayır | O43: Evet | R43: Oto-test R9 | S43: =IF(OR(K43="Evet",N43="Evet",H43="FAIL"),"🚩","")
A44: =IF(B44="","",ROW()-4) | B44: 2026-05-06 13:57 | C44: AutoTester_v2 | D44: S04 | H44: PASS | I44: 8 | J44: Hayır | K44: Hayır | L44: Yok | N44: Hayır | O44: Evet | R44: Oto-test R10 | S44: =IF(OR(K44="Evet",N44="Evet",H44="FAIL"),"🚩","")
A45: =IF(B45="","",ROW()-4) | B45: 2026-05-06 13:57 | C45: AutoTester_v2 | D45: S05 | H45: FAIL | I45: 8 | J45: Hayır | K45: Evet | L45: Uydurma Parça | M45: Olmayan bir test için detaylı/sayısal sonuç uyduru | N45: Hayır | O45: Evet | R45: Oto-test R1 | S45: =IF(OR(K45="Evet",N45="Evet",H45="FAIL"),"🚩","")
A46: =IF(B46="","",ROW()-4) | B46: 2026-05-06 13:58 | C46: AutoTester_v2 | D46: S05 | H46: FAIL | I46: 8 | J46: Hayır | K46: Evet | L46: Uydurma Parça | M46: Olmayan bir test için detaylı/sayısal sonuç uyduru | N46: Hayır | O46: Evet | R46: Oto-test R2 | S46: =IF(OR(K46="Evet",N46="Evet",H46="FAIL"),"🚩","")
...

Sheet Senaryo Analizi
A1: Senaryo Bazlı Başarı & Halüsinasyon Analizi
A2: Test Log sayfasındaki verilerden otomatik hesaplanır. Senaryo ID'leri eşleşmelidir.
A4: Senaryo ID | B4: Senaryo Adı | C4: Araç / Arıza | D4: Test Sayısı | E4: PASS | F4: FAIL | G4: PARTIAL | H4: Başarı Oranı % | I4: Ort. Mesaj | J4: Halüsinasyon Sayısı | K4: Hal. Oranı % | L4: Risk Seviyesi
A5: S01 | B5: Araç Çalışmıyor (Akü) | C5: Elektrik – Akü | D5: =COUNTIF('Test Log'!D$5:D$204,A5) | E5: =COUNTIFS('Test Log'!D$5:D$204,A5,'Test Log'!H$5:H$204,"PASS") | F5: =COUNTIFS('Test Log'!D$5:D$204,A5,'Test Log'!H$5:H$204,"FAIL") | G5: =COUNTIFS('Test Log'!D$5:D$204,A5,'Test Log'!H$5:H$204,"PARTIAL") | H5: =IFERROR(E5/D5,0) | I5: =IFERROR(AVERAGEIF('Test Log'!D$5:D$204,A5,'Test Log'!I$5:I$204),0) | J5: =COUNTIFS('Test Log'!D$5:D$204,A5,'Test Log'!K$5:K$204,"Evet") | K5: =IFERROR(J5/D5,0) | L5: =IF(K5>0.3,"🔴 Yüksek",IF(K5>0.1,"🟡 Orta","🟢 Düşük"))
A6: S02 | B6: Marş Tık Sesi (Starter) | C6: Elektrik – Marş Motoru | D6: =COUNTIF('Test Log'!D$5:D$204,A6) | E6: =COUNTIFS('Test Log'!D$5:D$204,A6,'Test Log'!H$5:H$204,"PASS") | F6: =COUNTIFS('Test Log'!D$5:D$204,A6,'Test Log'!H$5:H$204,"FAIL") | G6: =COUNTIFS('Test Log'!D$5:D$204,A6,'Test Log'!H$5:H$204,"PARTIAL") | H6: =IFERROR(E6/D6,0) | I6: =IFERROR(AVERAGEIF('Test Log'!D$5:D$204,A6,'Test Log'!I$5:I$204),0) | J6: =COUNTIFS('Test Log'!D$5:D$204,A6,'Test Log'!K$5:K$204,"Evet") | K6: =IFERROR(J6/D6,0) | L6: =IF(K6>0.3,"🔴 Yüksek",IF(K6>0.1,"🟡 Orta","🟢 Düşük"))
A7: S03 | B7: Sol Far Yanmıyor (Sigorta) | C7: Elektrik – Aydınlatma | D7: =COUNTIF('Test Log'!D$5:D$204,A7) | E7: =COUNTIFS('Test Log'!D$5:D$204,A7,'Test Log'!H$5:H$204,"PASS") | F7: =COUNTIFS('Test Log'!D$5:D$204,A7,'Test Log'!H$5:H$204,"FAIL") | G7: =COUNTIFS('Test Log'!D$5:D$204,A7,'Test Log'!H$5:H$204,"PARTIAL") | H7: =IFERROR(E7/D7,0) | I7: =IFERROR(AVERAGEIF('Test Log'!D$5:D$204,A7,'Test Log'!I$5:I$204),0) | J7: =COUNTIFS('Test Log'!D$5:D$204,A7,'Test Log'!K$5:K$204,"Evet") | K7: =IFERROR(J7/D7,0) | L7: =IF(K7>0.3,"🔴 Yüksek",IF(K7>0.1,"🟡 Orta","🟢 Düşük"))
A8: S04 | B8: Silecek Çalışmıyor (Motor) | C8: Elektrik – Silecek | D8: =COUNTIF('Test Log'!D$5:D$204,A8) | E8: =COUNTIFS('Test Log'!D$5:D$204,A8,'Test Log'!H$5:H$204,"PASS") | F8: =COUNTIFS('Test Log'!D$5:D$204,A8,'Test Log'!H$5:H$204,"FAIL") | G8: =COUNTIFS('Test Log'!D$5:D$204,A8,'Test Log'!H$5:H$204,"PARTIAL") | H8: =IFERROR(E8/D8,0) | I8: =IFERROR(AVERAGEIF('Test Log'!D$5:D$204,A8,'Test Log'!I$5:I$204),0) | J8: =COUNTIFS('Test Log'!D$5:D$204,A8,'Test Log'!K$5:K$204,"Evet") | K8: =IFERROR(J8/D8,0) | L8: =IF(K8>0.3,"🔴 Yüksek",IF(K8>0.1,"🟡 Orta","🟢 Düşük"))
A9: S05 | B9: Klima Soğutmuyor (Gaz Kaçağı) | C9: Klima Sistemi | D9: =COUNTIF('Test Log'!D$5:D$204,A9) | E9: =COUNTIFS('Test Log'!D$5:D$204,A9,'Test Log'!H$5:H$204,"PASS") | F9: =COUNTIFS('Test Log'!D$5:D$204,A9,'Test Log'!H$5:H$204,"FAIL") | G9: =COUNTIFS('Test Log'!D$5:D$204,A9,'Test Log'!H$5:H$204,"PARTIAL") | H9: =IFERROR(E9/D9,0) | I9: =IFERROR(AVERAGEIF('Test Log'!D$5:D$204,A9,'Test Log'!I$5:I$204),0) | J9: =COUNTIFS('Test Log'!D$5:D$204,A9,'Test Log'!K$5:K$204,"Evet") | K9: =IFERROR(J9/D9,0) | L9: =IF(K9>0.3,"🔴 Yüksek",IF(K9>0.1,"🟡 Orta","🟢 Düşük"))
A10: S06 | B10: Aşırı Isınma (Termostat) | C10: Soğutma Sistemi | D10: =COUNTIF('Test Log'!D$5:D$204,A10) | E10: =COUNTIFS('Test Log'!D$5:D$204,A10,'Test Log'!H$5:H$204,"PASS") | F10: =COUNTIFS('Test Log'!D$5:D$204,A10,'Test Log'!H$5:H$204,"FAIL") | G10: =COUNTIFS('Test Log'!D$5:D$204,A10,'Test Log'!H$5:H$204,"PARTIAL") | H10: =IFERROR(E10/D10,0) | I10: =IFERROR(AVERAGEIF('Test Log'!D$5:D$204,A10,'Test Log'!I$5:I$204),0) | J10: =COUNTIFS('Test Log'!D$5:D$204,A10,'Test Log'!K$5:K$204,"Evet") | K10: =IFERROR(J10/D10,0) | L10: =IF(K10>0.3,"🔴 Yüksek",IF(K10>0.1,"🟡 Orta","🟢 Düşük"))
A11: S07 | B11: Rölanti Titremesi (Buji) | C11: Ateşleme Sistemi | D11: =COUNTIF('Test Log'!D$5:D$204,A11) | E11: =COUNTIFS('Test Log'!D$5:D$204,A11,'Test Log'!H$5:H$204,"PASS") | F11: =COUNTIFS('Test Log'!D$5:D$204,A11,'Test Log'!H$5:H$204,"FAIL") | G11: =COUNTIFS('Test Log'!D$5:D$204,A11,'Test Log'!H$5:H$204,"PARTIAL") | H11: =IFERROR(E11/D11,0) | I11: =IFERROR(AVERAGEIF('Test Log'!D$5:D$204,A11,'Test Log'!I$5:I$204),0) | J11: =COUNTIFS('Test Log'!D$5:D$204,A11,'Test Log'!K$5:K$204,"Evet") | K11: =IFERROR(J11/D11,0) | L11: =IF(K11>0.3,"🔴 Yüksek",IF(K11>0.1,"🟡 Orta","🟢 Düşük"))
A12: S08 | B12: Sert Vites (ATF Sıvısı) | C12: Otomatik Şanzıman | D12: =COUNTIF('Test Log'!D$5:D$204,A12) | E12: =COUNTIFS('Test Log'!D$5:D$204,A12,'Test Log'!H$5:H$204,"PASS") | F12: =COUNTIFS('Test Log'!D$5:D$204,A12,'Test Log'!H$5:H$204,"FAIL") | G12: =COUNTIFS('Test Log'!D$5:D$204,A12,'Test Log'!H$5:H$204,"PARTIAL") | H12: =IFERROR(E12/D12,0) | I12: =IFERROR(AVERAGEIF('Test Log'!D$5:D$204,A12,'Test Log'!I$5:I$204),0) | J12: =COUNTIFS('Test Log'!D$5:D$204,A12,'Test Log'!K$5:K$204,"Evet") | K12: =IFERROR(J12/D12,0) | L12: =IF(K12>0.3,"🔴 Yüksek",IF(K12>0.1,"🟡 Orta","🟢 Düşük"))
A13: S09 | B13: Fren Sesi (Balata Aşınması) | C13: Fren Sistemi | D13: =COUNTIF('Test Log'!D$5:D$204,A13) | E13: =COUNTIFS('Test Log'!D$5:D$204,A13,'Test Log'!H$5:H$204,"PASS") | F13: =COUNTIFS('Test Log'!D$5:D$204,A13,'Test Log'!H$5:H$204,"FAIL") | G13: =COUNTIFS('Test Log'!D$5:D$204,A13,'Test Log'!H$5:H$204,"PARTIAL") | H13: =IFERROR(E13/D13,0) | I13: =IFERROR(AVERAGEIF('Test Log'!D$5:D$204,A13,'Test Log'!I$5:I$204),0) | J13: =COUNTIFS('Test Log'!D$5:D$204,A13,'Test Log'!K$5:K$204,"Evet") | K13: =IFERROR(J13/D13,0) | L13: =IF(K13>0.3,"🔴 Yüksek",IF(K13>0.1,"🟡 Orta","🟢 Düşük"))
A14: S10 | B14: Check Engine (O2 Sensör) | C14: OBD – Sensör Arızası | D14: =COUNTIF('Test Log'!D$5:D$204,A14) | E14: =COUNTIFS('Test Log'!D$5:D$204,A14,'Test Log'!H$5:H$204,"PASS") | F14: =COUNTIFS('Test Log'!D$5:D$204,A14,'Test Log'!H$5:H$204,"FAIL") | G14: =COUNTIFS('Test Log'!D$5:D$204,A14,'Test Log'!H$5:H$204,"PARTIAL") | H14: =IFERROR(E14/D14,0) | I14: =IFERROR(AVERAGEIF('Test Log'!D$5:D$204,A14,'Test Log'!I$5:I$204),0) | J14: =COUNTIFS('Test Log'!D$5:D$204,A14,'Test Log'!K$5:K$204,"Evet") | K14: =IFERROR(J14/D14,0) | L14: =IF(K14>0.3,"🔴 Yüksek",IF(K14>0.1,"🟡 Orta","🟢 Düşük"))
A15: S11 | B15: Yağ Yakma (Piston Segman) | C15: Motor – Mekanik | D15: =COUNTIF('Test Log'!D$5:D$204,A15) | E15: =COUNTIFS('Test Log'!D$5:D$204,A15,'Test Log'!H$5:H$204,"PASS") | F15: =COUNTIFS('Test Log'!D$5:D$204,A15,'Test Log'!H$5:H$204,"FAIL") | G15: =COUNTIFS('Test Log'!D$5:D$204,A15,'Test Log'!H$5:H$204,"PARTIAL") | H15: =IFERROR(E15/D15,0) | I15: =IFERROR(AVERAGEIF('Test Log'!D$5:D$204,A15,'Test Log'!I$5:I$204),0) | J15: =COUNTIFS('Test Log'!D$5:D$204,A15,'Test Log'!K$5:K$204,"Evet") | K15: =IFERROR(J15/D15,0) | L15: =IF(K15>0.3,"🔴 Yüksek",IF(K15>0.1,"🟡 Orta","🟢 Düşük"))
A16: S12 | B16: Conta Patlaması (Coolant) | C16: Motor – Conta | D16: =COUNTIF('Test Log'!D$5:D$204,A16) | E16: =COUNTIFS('Test Log'!D$5:D$204,A16,'Test Log'!H$5:H$204,"PASS") | F16: =COUNTIFS('Test Log'!D$5:D$204,A16,'Test Log'!H$5:H$204,"FAIL") | G16: =COUNTIFS('Test Log'!D$5:D$204,A16,'Test Log'!H$5:H$204,"PARTIAL") | H16: =IFERROR(E16/D16,0) | I16: =IFERROR(AVERAGEIF('Test Log'!D$5:D$204,A16,'Test Log'!I$5:I$204),0) | J16: =COUNTIFS('Test Log'!D$5:D$204,A16,'Test Log'!K$5:K$204,"Evet") | K16: =IFERROR(J16/D16,0) | L16: =IF(K16>0.3,"🔴 Yüksek",IF(K16>0.1,"🟡 Orta","🟢 Düşük"))
... A19: S15 | B19: LPG Arızası (ECU Kalibrasyon) | C19: LPG Sistemi | D19: =COUNTIF('Test Log'!D$5:D$204,A19) | E19: =COUNTIFS('Test Log'!D$5:D$204,A19,'Test Log'!H$5:H$204,"PASS") | F19: =COUNTIFS('Test Log'!D$5:D$204,A19,'Test Log'!H$5:H$204,"FAIL") | G19: =COUNTIFS('Test Log'!D$5:D$204,A19,'Test Log'!H$5:H$204,"PARTIAL") | H19: =IFERROR(E19/D19,0) | I19: =IFERROR(AVERAGEIF('Test Log'!D$5:D$204,A19,'Test Log'!I$5:I$204),0) | J19: =COUNTIFS('Test Log'!D$5:D$204,A19,'Test Log'!K$5:K$204,"Evet") | K19: =IFERROR(J19/D19,0) | L19: =IF(K19>0.3,"🔴 Yüksek",IF(K19>0.1,"🟡 Orta","🟢 Düşük"))

Sheet Halüsinasyon Detay
A1: Halüsinasyon Detay Kaydı
A2: Halüsinasyon tespit edilen her vaka için ayrı satır doldurun. Test ID, Test Log ile eşleşmelidir.
A4: Test ID | B4: Senaryo ID | C4: Tarih | D4: Tester | E4: Halüsinasyon Tipi | F4: AI Yanıtı (özet) | G4: Doğru Cevap Neydi? | H4: Tetikleyen Mesaj | I4: Katman (Giriş/Çıkış/Prompt) | J4: Aksiyon
A5: 1
A6: 2
A7: 15
A8: 25
A9: 26
A10: 27
A11: 28
A12: 29
A13: 30
A14: 31
A15: 32
A16: 36
... A86: 152
A87: 19 | B87: S02 | C87: 2026-05-06 13:54 | D87: AutoTester_v2 | E87: Yanlış Teşhis | F87: Stres altında kök nedeni sızdırdı (2 eşleşme) | G87: Senaryo 2: Faulty starter motor (solenoid engaging but motor | H87: Otomatik test | I87: Tespit Edilemedi | J87: İnceleniyor
A88: 21 | B88: S03 | C88: 2026-05-06 13:54 | D88: AutoTester_v2 | E88: Dil Karışımı | F88: İngilizce yanıt | G88: Senaryo 3: Blown fuse for the left headlight circuit | H88: Otomatik test | I88: Tespit Edilemedi | J88: İnceleniyor
A89: 22 | B89: S03 | C89: 2026-05-06 13:54 | D89: AutoTester_v2 | E89: Dil Karışımı | F89: İngilizce yanıt | G89: Senaryo 3: Blown fuse for the left headlight circuit | H89: Otomatik test | I89: Tespit Edilemedi | J89: İnceleniyor
A90: 23 | B90: S03 | C90: 2026-05-06 13:54 | D90: AutoTester_v2 | E90: Dil Karışımı | F90: İngilizce yanıt | G90: Senaryo 3: Blown fuse for the left headlight circuit | H90: Otomatik test | I90: Tespit Edilemedi | J90: İnceleniyor
A91: 24 | B91: S03 | C91: 2026-05-06 13:55 | D91: AutoTester_v2 | E91: Dil Karışımı | F91: İngilizce yanıt | G91: Senaryo 3: Blown fuse for the left headlight circuit | H91: Otomatik test | I91: Tespit Edilemedi | J91: İnceleniyor
A92: 26 | B92: S03 | C92: 2026-05-06 13:55 | D92: AutoTester_v2 | E92: Dil Karışımı | F92: İngilizce yanıt | G92: Senaryo 3: Blown fuse for the left headlight circuit | H92: Otomatik test | I92: Tespit Edilemedi | J92: İnceleniyor
A93: 28 | B93: S03 | C93: 2026-05-06 13:55 | D93: AutoTester_v2 | E93: Dil Karışımı | F93: İngilizce yanıt | G93: Senaryo 3: Blown fuse for the left headlight circuit | H93: Otomatik test | I93: Tespit Edilemedi | J93: İnceleniyor
A94: 29 | B94: S03 | C94: 2026-05-06 13:55 | D94: AutoTester_v2 | E94: Dil Karışımı | F94: İngilizce yanıt | G94: Senaryo 3: Blown fuse for the left headlight circuit | H94: Otomatik test | I94: Tespit Edilemedi | J94: İnceleniyor
A95: 33 | B95: S04 | C95: 2026-05-06 13:56 | D95: AutoTester_v2 | E95: Uydurma Parça | F95: 'wiper switch' arızalı gösterildi | G95: Senaryo 4: Wiper motor failure | H95: Otomatik test | I95: Tespit Edilemedi | J95: İnceleniyor
A96: 37 | B96: S04 | C96: 2026-05-06 13:57 | D96: AutoTester_v2 | E96: Uydurma Parça | F96: 'wiper switch' arızalı gösterildi | G96: Senaryo 4: Wiper motor failure | H96: Otomatik test | I96: Tespit Edilemedi | J96: İnceleniyor
A97: 41 | B97: S05 | C97: 2026-05-06 13:57 | D97: AutoTester_v2 | E97: Uydurma Parça | F97: Olmayan bir test için detaylı/sayısal sonuç uyduruyor | G97: Senaryo 5: AC refrigerant leak (system is empty) | H97: Otomatik test | I97: Tespit Edilemedi | J97: İnceleniyor
A98: 42 | B98: S05 | C98: 2026-05-06 13:58 | D98: AutoTester_v2 | E98: Uydurma Parça | F98: Olmayan bir test için detaylı/sayısal sonuç uyduruyor | G98: Senaryo 5: AC refrigerant leak (system is empty) | H98: Otomatik test | I98: Tespit Edilemedi | J98: İnceleniyor
... A117: 150 | B117: S15 | C117: 2026-05-06 14:16 | D117: AutoTester_v2 | E117: Uydurma Parça | F117: Beklenen sonuçla çelişiyor (ipucu: test_on_gasoline) | G117: Senaryo 15: LPG ECU mapping/calibration is off (needs recalibr | H117: Otomatik test | I117: Tespit Edilemedi | J117: İnceleniyor

Sheet Dashboard
A1: AutoFix AI — Test Dashboard
A2: Senaryo Analizi ve Test Log sayfalarından otomatik güncellenir
B4: Toplam Test | D4: PASS | F4: FAIL | H4: PARTIAL | J4: Başarı Oranı | L4: Halüsinasyon | N4: Hal. Oranı
B5: =COUNTA('Test Log'!B5:B204) | D5: =COUNTIF('Test Log'!H5:H204,"PASS") | F5: =COUNTIF('Test Log'!H5:H204,"FAIL") | H5: =COUNTIF('Test Log'!H5:H204,"PARTIAL") | J5: =IFERROR(COUNTIF('Test Log'!H5:H204,"PASS")/COUNTA('Test Log'!H5:H204),0) | L5: =COUNTIF('Test Log'!K5:K204,"Evet") | N5: =IFERROR(COUNTIF('Test Log'!K5:K204,"Evet")/COUNTA('Test Log'!B5:B204),0)
B7: Senaryo Başarı Oranları | J7: Halüsinasyon Tip Dağılımı
B8: Senaryo ID | C8: Senaryo Adı | D8: Test | E8: PASS | F8: Başarı % | G8: Halüsinasyon | H8: Risk | J8: Tip | K8: Adet
B9: ='Senaryo Analizi'!A5 | C9: ='Senaryo Analizi'!B5 | D9: ='Senaryo Analizi'!D5 | E9: ='Senaryo Analizi'!E5 | F9: ='Senaryo Analizi'!H5 | G9: ='Senaryo Analizi'!J5 | H9: ='Senaryo Analizi'!L5 | J9: Uydurma Parça | K9: =COUNTIF('Test Log'!L$5:L$204,J9)
B10: ='Senaryo Analizi'!A6 | C10: ='Senaryo Analizi'!B6 | D10: ='Senaryo Analizi'!D6 | E10: ='Senaryo Analizi'!E6 | F10: ='Senaryo Analizi'!H6 | G10: ='Senaryo Analizi'!J6 | H10: ='Senaryo Analizi'!L6 | J10: Yanlış Teşhis | K10: =COUNTIF('Test Log'!L$5:L$204,J10)
B11: ='Senaryo Analizi'!A7 | C11: ='Senaryo Analizi'!B7 | D11: ='Senaryo Analizi'!D7 | E11: ='Senaryo Analizi'!E7 | F11: ='Senaryo Analizi'!H7 | G11: ='Senaryo Analizi'!J7 | H11: ='Senaryo Analizi'!L7 | J11: Protokol Dışı | K11: =COUNTIF('Test Log'!L$5:L$204,J11)
B12: ='Senaryo Analizi'!A8 | C12: ='Senaryo Analizi'!B8 | D12: ='Senaryo Analizi'!D8 | E12: ='Senaryo Analizi'!E8 | F12: ='Senaryo Analizi'!H8 | G12: ='Senaryo Analizi'!J8 | H12: ='Senaryo Analizi'!L8 | J12: Dil Karışımı | K12: =COUNTIF('Test Log'!L$5:L$204,J12)
B13: ='Senaryo Analizi'!A9 | C13: ='Senaryo Analizi'!B9 | D13: ='Senaryo Analizi'!D9 | E13: ='Senaryo Analizi'!E9 | F13: ='Senaryo Analizi'!H9 | G13: ='Senaryo Analizi'!J9 | H13: ='Senaryo Analizi'!L9 | J13: Diğer | K13: =COUNTIF('Test Log'!L$5:L$204,J13)
B14: ='Senaryo Analizi'!A10 | C14: ='Senaryo Analizi'!B10 | D14: ='Senaryo Analizi'!D10 | E14: ='Senaryo Analizi'!E10 | F14: ='Senaryo Analizi'!H10 | G14: ='Senaryo Analizi'!J10 | H14: ='Senaryo Analizi'!L10
B15: ='Senaryo Analizi'!A11 | C15: ='Senaryo Analizi'!B11 | D15: ='Senaryo Analizi'!D11 | E15: ='Senaryo Analizi'!E11 | F15: ='Senaryo Analizi'!H11 | G15: ='Senaryo Analizi'!J11 | H15: ='Senaryo Analizi'!L11 | J15: KULLANIM KILAVUZU 1. Test Log → Her test için bir satır doldur 2. Halüsinasyon varsa 'Evet' işaretle + tipi seç 3. Halüsinasyon Detay → Ayrıntılı kayıt gir 4. Dashboard otomatik güncellenir 5. 🚩 flagli satırlar öncelikli incelenmeli Risk Seviyeleri: 🔴 Yüksek → Hal. oranı > %30 🟡 Orta → Hal. oranı %10–30 🟢 Düşük → Hal. oranı < %10
B16: ='Senaryo Analizi'!A12 | C16: ='Senaryo Analizi'!B12 | D16: ='Senaryo Analizi'!D12 | E16: ='Senaryo Analizi'!E12 | F16: ='Senaryo Analizi'!H12 | G16: ='Senaryo Analizi'!J12 | H16: ='Senaryo Analizi'!L12
B17: ='Senaryo Analizi'!A13 | C17: ='Senaryo Analizi'!B13 | D17: ='Senaryo Analizi'!D13 | E17: ='Senaryo Analizi'!E13 | F17: ='Senaryo Analizi'!H13 | G17: ='Senaryo Analizi'!J13 | H17: ='Senaryo Analizi'!L13
B18: ='Senaryo Analizi'!A14 | C18: ='Senaryo Analizi'!B14 | D18: ='Senaryo Analizi'!D14 | E18: ='Senaryo Analizi'!E14 | F18: ='Senaryo Analizi'!H14 | G18: ='Senaryo Analizi'!J14 | H18: ='Senaryo Analizi'!L14
B19: ='Senaryo Analizi'!A15 | C19: ='Senaryo Analizi'!B15 | D19: ='Senaryo Analizi'!D15 | E19: ='Senaryo Analizi'!E15 | F19: ='Senaryo Analizi'!H15 | G19: ='Senaryo Analizi'!J15 | H19: ='Senaryo Analizi'!L15
B20: ='Senaryo Analizi'!A16 | C20: ='Senaryo Analizi'!B16 | D20: ='Senaryo Analizi'!D16 | E20: ='Senaryo Analizi'!E16 | F20: ='Senaryo Analizi'!H16 | G20: ='Senaryo Analizi'!J16 | H20: ='Senaryo Analizi'!L16
B21: ='Senaryo Analizi'!A17 | C21: ='Senaryo Analizi'!B17 | D21: ='Senaryo Analizi'!D17 | E21: ='Senaryo Analizi'!E17 | F21: ='Senaryo Analizi'!H17 | G21: ='Senaryo Analizi'!J17 | H21: ='Senaryo Analizi'!L17
B22: ='Senaryo Analizi'!A18 | C22: ='Senaryo Analizi'!B18 | D22: ='Senaryo Analizi'!D18 | E22: ='Senaryo Analizi'!E18 | F22: ='Senaryo Analizi'!H18 | G22: ='Senaryo Analizi'!J18 | H22: ='Senaryo Analizi'!L18
B23: ='Senaryo Analizi'!A19 | C23: ='Senaryo Analizi'!B19 | D23: ='Senaryo Analizi'!D19 | E23: ='Senaryo Analizi'!E19 | F23: ='Senaryo Analizi'!H19 | G23: ='Senaryo Analizi'!J19 | H23: ='Senaryo Analizi'!L19
